const { catchError } = require("../utils/catch-error");
const User = require("../models/user");

exports.getIndex = async (req, res) => {
  try {
    const user = await User.findById(req.userId);
    res.status(201).json({ message: `You're in! Logged in as ${user.name}` });
  } catch (err) {
    catchError(err, res);
  }
};
